<?xml version="1.0"?>
<robot name="auto_car" xmlns:xacro="http://www.ros.org/wiki/xacro">

  <!-- <xacro:include filename="inertial_macros.xacro"/> -->

  <!-- Robot Description -->


  <link name="base_link">
    <inertial>
      <mass value="0.5"/>
      <origin rpy="0 0 0" xyz="0 0 0.5"/>
      <inertia ixx="0.1" ixy="0.0" ixz="0.0" iyy="0.1" iyz="0.0" izz="0.1"/>
    </inertial>
    <visual>
      <origin rpy="0 0 0" xyz="0 0 0"/>
      <geometry>
        <box size="0.3 0.4 0.1"/>
      </geometry>
      <material name="blue">
        <color rgba="0 0 0.8 1"/>
      </material>
    </visual>
    <collision>
      <origin rpy="0 0 0" xyz="0 0 0"/>
      <geometry>
        <box size="0.3 0.3 0.1"/>
      </geometry>
    </collision>
    <!-- <xacro:inertial_box mass="0.5" x="0.3" y="0.3" z="0.1">
      <origin xyz="0.0 0.0 0.0" rpy="0.0 0.0 0.0"/>
    </xacro:inertial_box> -->
  </link>


  <joint name="base_footprint_joint" type="fixed">
    <origin xyz="0.0 0.0 0.0" rpy="0.0 0.0 0.0"/>
    <parent link="base_link"/>
    <child link="base_footprint"/>
  </joint>
  
  <link name = "base_footprint"/>

  <joint name="left_wheel_joint" type="continuous">
    <origin rpy="0 1.57 0" xyz="0.16 0.0 -0.045"/>
    <parent link="base_link"/>
    <child link="left_wheel_link"/>
    <axis xyz="0 0 1"/>
  </joint>

  <link name="left_wheel_link">
    <inertial>
      <mass value="0.1"/>
      <origin rpy="0 0 0" xyz="0 0 0"/>
      <inertia ixx="0.005" ixy="0.0" ixz="0.0" iyy="0.005" iyz="0.0" izz="0.005"/>
    </inertial>
    <collision>
      <origin rpy="1.57 0 0" xyz="0 0 0"/>
      <geometry>
        <!-- <cylinder length="0.05" radius="0.05"/> -->
        <mesh filename="package://ebot_description/meshes/tyre11.dae"/>
      </geometry>
    </collision>
    <visual>
      <origin rpy="1.57 0 0" xyz="0 0 0"/>
      <geometry>
        <!-- <cylinder length="0.03" radius="0.05"/> -->
        <mesh filename="package://ebot_description/meshes/tyre11.dae"/>
      </geometry>
      <material name="gray">
        <color rgba="0.5 0.5 0.5 1"/>
      </material>
    </visual>
    <!-- <xacro:inertial_box mass="0.1" length="0.03" radius="0.05">
      <origin xyz="0.0 0.0 0.0" rpy="0.0 0.0 0.0"/>
    </xacro:inertial_box> -->
  </link>

  <joint name="right_wheel_joint" type="continuous">
    <origin rpy="0 1.57 0" xyz="-0.16 0.0 -0.046"/>
    <parent link="base_link"/>
    <child link="right_wheel_link"/>
    <axis xyz="0 0 1"/>
  </joint>

  <link name="right_wheel_link">
    <inertial>
      <mass value="0.1"/>
      <origin rpy="0 0 0" xyz="0 0 0"/>
      <inertia ixx="0.005" ixy="0.0" ixz="0.0" iyy="0.005" iyz="0.0" izz="0.005"/>
    </inertial>
    <collision>
      <origin rpy="1.57 0 0" xyz="0 0 0"/>
      <geometry>
        <!-- <cylinder length="0.03" radius="0.05"/> -->
        <mesh filename="package://ebot_description/meshes/tyre11.dae"/>
      </geometry>
    </collision>
    <visual>
      <origin rpy="1.57 0 0" xyz="0 0 0"/>
      <geometry>
        <!-- <cylinder length="0.03" radius="0.05"/> -->
        <mesh filename="package://ebot_description/meshes/tyre11.dae"/>
      </geometry>
      <material name="gray">
        <color rgba="0.5 0.5 0.5 1"/>
      </material>
    </visual>
  </link>

  <joint name="caster_wheel_joint" type="fixed">
    <origin xyz="0.0 -0.15 -0.05" rpy="0.0 0.0 0.0"/>
    <parent link="base_link"/>
    <child link="caster_wheel"/>
    <axis xyz="0 0 1"/>
  </joint>

  <link name="caster_wheel">
    <visual>
      <geometry>
        <sphere radius="0.05"/>
      </geometry>
      <material name="black">
        <color rgba="0 0 0 1"/>
      </material>
    </visual>
    <collision>
      <origin rpy="0 0 0" xyz="0 0 0"/>
      <geometry>
        <sphere radius="0.05"/>
      </geometry>
    </collision>
    <!-- <xacro:inertial_box mass="0.1" radius="0.05">
      <origin xyz="0.0 0.0 0.0" rpy="0.0 0.0 0.0"/>
    </xacro:inertial_box> -->
  </link>

  <joint name="caster_wheel2_joint" type="fixed">
    <origin xyz="0.0 0.15 -0.05" rpy="0.0 0.0 0.0"/>
    <parent link="base_link"/>
    <child link="caster_wheel2"/>
    <axis xyz="0 0 1"/>
  </joint>

  <link name="caster_wheel2">
    <visual>
      <geometry>
        <sphere radius="0.05"/>
      </geometry>
      <material name="black">
        <color rgba="0 0 0 1"/>
      </material>
    </visual>
    <collision>
      <origin rpy="0 0 0" xyz="0 0 0"/>
      <geometry>
        <sphere radius="0.05"/>
      </geometry>
    </collision>
    <!-- <xacro:inertial_box mass="0.1" radius="0.05">
      <origin xyz="0.0 0.0 0.0" rpy="0.0 0.0 0.0"/>
    </xacro:inertial_box> -->
  </link>

  <gazebo reference="left_wheel_link">
    <material>Gazebo/Grey</material>
  </gazebo>

  <gazebo reference="right_wheel_link">
    <material>Gazebo/Grey</material>
  </gazebo>

  <gazebo reference="caster_wheel">
    <material>Gazebo/Black</material>
    <mu1 value = "0.01"/>
    <mu2 value = "0.01"/>
  </gazebo>

  <gazebo reference="caster_wheel2">
    <material>Gazebo/Black</material>
    <mu1 value = "0.01"/>
    <mu2 value = "0.01"/>
  </gazebo>

  <gazebo>
    <plugin name="diff_drive" filename="libgazebo_ros_diff_drive.so">
      <legacyMode>true</legacyMode>
      <alwaysOn>true</alwaysOn>
      <updateRate>1000.0</updateRate>
      <leftJoint>left_wheel_joint</leftJoint>
      <rightJoint>right_wheel_joint</rightJoint>
      <wheelSeparation>0.4</wheelSeparation>
      <wheelDiameter>0.1</wheelDiameter>
      <torque>5</torque>

      <max_wheel_torque>50</max_wheel_torque>
      <max_wheel_acceleration>5.0</max_wheel_acceleration>

      <commandTopic>cmd_vel</commandTopic>
      <odometryTopic>odom</odometryTopic>
      <odometryFrame>odom</odometryFrame>
      <robotBaseFrame>base_link</robotBaseFrame>
    </plugin>
  </gazebo>

  <joint name="camera_joint" type="fixed">
    <parent link="base_link"/>
    <child link="camera_Link"/>
    <origin xyz="0.0 -0.2 0.03" rpy="0 0.0 -1.57"/>
  </joint>

  <link name="camera_Link">
  <visual name="">
      <geometry>
          <box size="0.01 0.02 0.03"/>
      </geometry>
      <material name="">
          <color rgba="1.0 0.0 0.0 1.0"/>
          <texture filename=""/>
      </material>
  </visual>
  </link>

  <!-- <joint name="camera_optical_joint" type="fixed">
    <parent link="camera_Link"/>
    <child link="camera_Link_optical"/>
    <origin xyz="0.0 0.0 0.0" rpy="1.57 1.57 -1.57"/>
  </joint>

  <link name="camera_Link_optical"></link> -->

  <gazebo reference="camera_Link"> 
    <material>Gazebo/Red</material>

    <sensor name="camera" type="camera">
        <pose>0 0 0 0 0 0</pose>
        <visualize>true</visualize>
        <update_rate>10</update_rate>
        <camera>
            <horizontal_fov>1.089</horizontal_fov>
            <image>
                <format>R8G8B8</format>
                <width>640</width>
                <height>480</height>
            </image>
            <clip>
                <near>0.05</near>
                <far>8.0</far>
            </clip>
        </camera>
        <plugin name="camera_controller" filename="libgazebo_ros_camera.so">
            <frameName>camera_Link</frameName>
        </plugin>
    </sensor> 
  </gazebo>

  <joint name="laser_joint" type="fixed">
    <parent link="base_link"/>
    <child link="laser_frame"/>
    <origin xyz="0 -0.12 0.07" rpy="0 0 0"/>
  </joint>

  <link name="laser_frame">
      <visual>
          <geometry>
              <cylinder radius="0.05" length="0.04"/>
          </geometry>
          <material name="red">
            <color rgba="1.0 0.0 0.0 1.0"/>
          </material>
      </visual>
      <collision>
          <geometry>
              <cylinder radius="0.05" length="0.04"/>
          </geometry>
      </collision>
  </link>


  <gazebo reference="laser_frame">
      <material>Gazebo/Red</material>

      <sensor name="laser" type="ray">
          <pose> 0 0 0 0 0 0 </pose>
          <visualize>true</visualize>
          <update_rate>10</update_rate>
          <always_on>1</always_on>
          <ray>
              <scan>
                  <horizontal>
                      <samples>360</samples>
                      <resolution>1</resolution>
                      <min_angle>-3.14</min_angle>
                      <max_angle>3.14</max_angle>
                  </horizontal>
              </scan>
              <range>
                  <min>0.1</min>
                  <max>5</max>
                  <resolution>0.01</resolution>
              </range>
          </ray>
          <plugin name="laser_controller" filename="libgazebo_ros_laser.so">
            <topicName>/scan</topicName>
            <frame_name>laser_frame</frame_name>
          </plugin>
      </sensor>
  </gazebo>
  
</robot>
